Workbook
Name Подразделения: 'Конт МО'!$F$4:$F$8
Name Должности: OFFSET('Конт МО'!$C$4,MATCH('Направления_на_МО'!$A$36,'Конт МО'!$B$4:$B$23,0)-1,0,COUNTIF('Конт МО'!$B$4:$B$23,'Направления_на_МО'!$A$36),1)

Sheet Направления_на_МО
F3: (наименование медицинской организации, код по ОГРН)
F5: адрес: | K5: ,
F6: телефон: | I6: , факс: | K6: ,
F7: адрес электронной почты:
G9: от | H9: ООО «Ресурс Тест»
G10: (наименование работодателя)
G11: адрес: | H11: 000000, г. Примерный, ул. Учебная, д. 1
G12: телефон: | H12: +0 (000) 000-00-00 | J12: , факс: | K12: -
G13: адрес электронной почты:
G14: demo@example.invalid
A16: Направление
A17: на предварительный медицинский осмотр
A20: В соответствии с п. п. 8, 9 Порядка проведения обязательных предварительных и периодических
A21: медицинских осмотров работников, предусмотренных частью четвертой статьи 213 Трудового кодекса
A22: Российской Федерации, утвержденного Приказом Минздрава России от 28.01.2021 N 29н,
A23: Общество с ограниченной ответственностью «Ресурс Тест» ОГРН 0000000000000 ИНН 0000000000 ОКФС: 16 - Частная собственность
A24: ОКВЭД 00.00 — демонстрационный вид деятельности
A25: (наименование работодателя; форма собственности и вид экономической деятельности работодателя по ОКВЭД)
A27: направляет на предварительный медицинский осмотр:
A28: 1. Фамилия, имя, отчество лица, поступающего на работу:
A29: Примерный Пример Примерович | K29: .
A30: 2. Дата рождения лица, поступающего на работу: | H30: 32874
A31: 3. Пол лица, поступающего на работу: | H31: Мужской
A32: 4. Номер медицинского страхового полиса обязательного и (или) добровольного медицинского
A33: страхования | C33: 0000000000000000
A34: 5. Наименование структурного подразделения работодателя (при наличии), в котором будет
A35: занято лицо, поступающее на работу:
A36: Технологический комплекс | K36: .
A37: 6. Наименование должности (профессии) или вида работы: | G37: Мастер участка | K37: .
A38: 7. Вредные и (или) опасные производственные факторы, а также вид работы в соответствии с
A39: утвержденным работодателем контингентом работников, подлежащих предварительным осмотрам:
A40: =IFERROR(VLOOKUP(A36&"|"&G37,'Конт МО'!$A$4:$D$23,4,FALSE),"Выберите подразделение и должность") -> п. 3.1.3; п. 4.3.2; п. 5.1п. 11.4; п.18.2; | K40: .
A42: =TODAY() -> 46311
A44: Специалист по подбору персонала | I44: Примеров П.П.
A45: (должность уполномоченного представителя работодателя) | G45: (подпись) | I45: (Ф.И.О)
A48: --------------------------------
A49: Информация для сведения:
A50: <1> Согласно п. 9 Порядка проведения обязательных предварительных и периодических медицинских осмотров работников, предусмотренных частью четвертой статьи 213 Трудового кодекса Российской Федерации, утвержденного Приказом Минздрава России от 28.01.2021 N 29н, направление выдается лицу, поступающему на работу, под подпись. Направление может быть сформировано в электронном виде с использованием электронных подписей работодателя и лица, поступающего на работу.
A51: Работодатель (его представитель) обязан организовать учет выданных направлений, в том числе в электронном виде.
A52: <2> Перечни медицинских противопоказаний к осуществлению работ с вредными и (или) опасными производственными факторами, а также работ, при выполнении которых проводятся обязательные предварительные и периодические медицинские осмотры, утверждены Приказом Минздрава России от 28.01.2021 N 29н.
...

Sheet Конт МО
B1: ООО «Ресурс Тест» (РТ) — демонстрационные контингенты
B2: Связи должностей с требованиями условные. Данные для демонстрации.
A3: Ключ: подразделение + должность | B3: Структурное подразделение | C3: Должность | D3: Вредные и (или) опасные производственные факторы | F3: Подразделения
A4: =B4&"|"&C4 -> Технологический комплекс|Оператор производственной линии | B4: Технологический комплекс | C4: Оператор производственной линии | D4: п. 11.4. | F4: Технологический комплекс
A5: =B5&"|"&C5 -> Технологический комплекс|Аппаратчик | B5: Технологический комплекс | C5: Аппаратчик | D5: п. 3.1.3, п.11.4,, 18.2 | F5: Горнодобывающий комплекс
A6: =B6&"|"&C6 -> Технологический комплекс|Мастер участка | B6: Технологический комплекс | C6: Мастер участка | D6: п. 3.1.3; п. 4.3.2; п. 5.1п. 11.4; п.18.2; | F6: Служба обслуживания и ремонта оборудования
A7: =B7&"|"&C7 -> Технологический комплекс|Технолог | B7: Технологический комплекс | C7: Технолог | D7: п. 3.1.3; п. 11.4. | F7: Автотранспортный участок
A8: =B8&"|"&C8 -> Горнодобывающий комплекс|Машинист экскаватора | B8: Горнодобывающий комплекс | C8: Машинист экскаватора | D8: п. 3.1.3; п. 4.4; п. 5.1; п.11.4 | F8: Служба по работе с персоналом
A9: =B9&"|"&C9 -> Горнодобывающий комплекс|Машинист бульдозера | B9: Горнодобывающий комплекс | C9: Машинист бульдозера | D9: п. 1.43.1; п. 4.4; п. 5.1; п. 11.4; п. 6.2
A10: =B10&"|"&C10 -> Горнодобывающий комплекс|Горный мастер | B10: Горнодобывающий комплекс | C10: Горный мастер | D10: п. 3.1.3; п. 4.4; п. 5.1; п. 6.2; п. 11.4.
A11: =B11&"|"&C11 -> Горнодобывающий комплекс|Инженер | B11: Горнодобывающий комплекс | C11: Инженер | D11: п. 3.1.9.2; п. 4.4; п. 5.1; п. 6.2; п. 9; п. 11.4; п. 6.2
A12: =B12&"|"&C12 -> Служба обслуживания и ремонта оборудования|Слесарь-ремонтник | B12: Служба обслуживания и ремонта оборудования | C12: Слесарь-ремонтник | D12: п. 3.1.9.2; п. 4.4; п. 5.1; п. 9; п. 11.4; п. 6.2
A13: =B13&"|"&C13 -> Служба обслуживания и ремонта оборудования|Электромонтёр | B13: Служба обслуживания и ремонта оборудования | C13: Электромонтёр | D13: п. 3.1.3; п. 4.4; п. 11.4; п.18.1
A14: =B14&"|"&C14 -> Служба обслуживания и ремонта оборудования|Механик | B14: Служба обслуживания и ремонта оборудования | C14: Механик | D14: п. 11.4;
A15: =B15&"|"&C15 -> Служба обслуживания и ремонта оборудования|Мастер по ремонту оборудования | B15: Служба обслуживания и ремонта оборудования | C15: Мастер по ремонту оборудования | D15: п. 1.1; п. 1.43.1; п.11.4
A16: =B16&"|"&C16 -> Автотранспортный участок|Водитель автомобиля | B16: Автотранспортный участок | C16: Водитель автомобиля | D16: п. 3.1.3; п. 4.4; п. 5.1; п. 11.4; п. 6.2
A17: =B17&"|"&C17 -> Автотранспортный участок|Водитель автобуса | B17: Автотранспортный участок | C17: Водитель автобуса | D17: п. 3.1.3; п. 4.4; п. 5.1; п. 9; п. 11.4; п. 6.2
A18: =B18&"|"&C18 -> Автотранспортный участок|Диспетчер | B18: Автотранспортный участок | C18: Диспетчер | D18: п.1.51.2, п. 4.4; ; п. 11.4;
A19: =B19&"|"&C19 -> Автотранспортный участок|Механик автотранспорта | B19: Автотранспортный участок | C19: Механик автотранспорта | D19: п. 3.1.3; п. 4.3.2; п. 4.4; п. 11.4; п. 18.2;
A20: =B20&"|"&C20 -> Служба по работе с персоналом|Специалист по подбору персонала | B20: Служба по работе с персоналом | C20: Специалист по подбору персонала | D20: п. 3.1.3; п. 4.3.2; ; п. 11.4; п. 18.2;
... A23: =B23&"|"&C23 -> Служба по работе с персоналом|Руководитель службы | B23: Служба по работе с персоналом | C23: Руководитель службы | D23: п. 5.1; п. 11.4; п. 6.2

Sheet Направления на ПО (автомат!!!)
F3: (наименование медицинской организации, код по ОГРН)
F5: адрес: | K5: ,
F6: телефон: | I6: , факс: | K6: ,
F7: адрес электронной почты:
G9: от | H9: ООО «Ресурс Тест»
F10: ОГРН 0000000000000 ИНН 0000000000
G11: (наименование работодателя)
G12: адрес: | H12: 000000, г. Примерный, ул. Учебная, д. 1
G13: телефон: | H13: +0 (000) 000-00-00 | J13: , факс: | K13: -
G14: адрес электронной почты:
G15: demo@example.invalid
A17: Направление
A18: на психиатрическое освидетельствование
A21: В соответствии статьи 220 Трудового кодекса Российской Федерации, приказа Министерства здравоохранения РФ от 20 мая 2022 № 342н
A22: ="Общество с ограниченной ответственностью «Ресурс Тест»"&CHAR(10)&"ОКФС: 16 - Частная собственность" -> Общество с ограниченной ответственностью «Ресурс Тест» ОКФС: 16 - Частная собственность
A23: ОКВЭД 00.00 — демонстрационный вид деятельности
A24: (наименование работодателя; форма собственности и вид экономической деятельности работодателя по ОКВЭД)
A26: направляет на психиатрическое освидетельствование:
A27: 1. Фамилия, имя, отчество лица, поступающего на работу:
A28: ='Направления_на_МО'!A29 -> Примерный Пример Примерович
A29: 2. Дата рождения лица, поступающего на работу: | H29: ='Направления_на_МО'!H30 -> 32874
A30: 3. Пол лица, поступающего на работу: | H30: ='Направления_на_МО'!H31 -> Мужской
A31: 4. Зарегестрированный (ая) по адресу: | F31: по месту регистрации
A32: 5. Наименование структурного подразделения работодателя (при наличии), в котором работник
A33: будет осуществлять отдельный вид (виды) деятельности:
A34: ='Направления_на_МО'!A36 -> Технологический комплекс
A35: 6. Наименование должности (профессии) или вида работы: | G35: ='Направления_на_МО'!G37 -> Мастер участка
A36: 7. Вид (виды) деятельности, осуществляемый работником
A37: =IFERROR(SUBSTITUTE(SUBSTITUTE(VLOOKUP(A34&"|"&G35,'Конт ПО'!$A$4:$D$23,4,FALSE),CHAR(10),""),")Деятельность",")"&CHAR(10)&"Деятельность"),"Выберите подразделение и должность") -> Деятельность, связанная с производством, хранением и применением взрывчатых материалов и веществ (п.2 Приложения №2 к приказу 342н от 20.05.2022г.) Деятельность непосредственно связанная с обслуживанием оборудования, работающего под избыточным давлением более 0,07 МПа (п.13 Приложения №2 к приказу 342н от 20.05.2022г.)
A39: Освидетельствование прошу провести согласно "Порядка прохождения обязательного психиатрического освидетельствования работниками, осуществляющими отдельные виды деятельности, его периодичность, а также видов деятельности, при осуществлении которых проводится психиатрическое освидетельствование", утв. приказом Министерства здравоохранения РФ от 20 мая 2022г. № 342н
A41: Решение врачебной комиссии о его (ее) годности (негодности) к выполнению поручаемой работы прошу выдать на руки обследуемому.
A43: ='Направления_на_МО'!A44 -> Специалист по подбору персонала | I43: ='Направления_на_МО'!I44 -> Примеров П.П.
A44: (должность уполномоченного представителя работодателя) | G44: (подпись) | I44: (фамилия, инициалы)
A49: ='Направления_на_МО'!A42 -> 46311
A50: «В случае предоставления работником поддельного медицинского заключения, наступает уголовная ответственность по ст. 327 УК РФ, с последующим увольнением. Важно, что при прохождении МО работник должен лично присутствовать в лечебном учреждении и производить оплату только в кассе данного учреждения!»
A51: Ознакомлен: | E51: Подпись:

Sheet Конт ПО
B1: ООО «Ресурс Тест» (РТ) — демонстрационные контингенты
B2: Связи должностей с требованиями условные. Данные для демонстрации.
A3: Ключ: подразделение + должность | B3: Структурное подразделение | C3: Должность | D3: Вид деятельности для ПО / отсутствие необходимости
A4: =B4&"|"&C4 -> Технологический комплекс|Оператор производственной линии | B4: Технологический комплекс | C4: Оператор производственной линии | D4: Деятельность, связанная с управлением транспортными средствами или управлением движением транспортных средств (п.1 Приложения №2 к приказу 342н от 20.05.2022г.)
A5: =B5&"|"&C5 -> Технологический комплекс|Аппаратчик | B5: Технологический комплекс | C5: Аппаратчик | D5: Психиатрическое освидетельствование не требуется
A6: =B6&"|"&C6 -> Технологический комплекс|Мастер участка | B6: Технологический комплекс | C6: Мастер участка | D6: Деятельность, связанная с производством, хранением и применением взрывчатых материалов и веществ (п.2 Приложения №2 к приказу 342н от 20.05.2022г.) Деятельность непосредственно связанная с обслуживанием оборудования, работающего под избыточным давлением более 0,07 МПа (п.13 Приложения №2 к приказу 342н от 20.05.2022г.)
A7: =B7&"|"&C7 -> Технологический комплекс|Технолог | B7: Технологический комплекс | C7: Технолог | D7: Психиатрическое освидетельствование не требуется
A8: =B8&"|"&C8 -> Горнодобывающий комплекс|Машинист экскаватора | B8: Горнодобывающий комплекс | C8: Машинист экскаватора | D8: Деятельность непосредственно связанная с обслуживанием оборудования, работающего под избыточным давлением более 0,07 МПа (п.13 Приложения №2 к приказу 342н от 20.05.2022г.)
A9: =B9&"|"&C9 -> Горнодобывающий комплекс|Машинист бульдозера | B9: Горнодобывающий комплекс | C9: Машинист бульдозера | D9: Психиатрическое освидетельствование не требуется
A10: =B10&"|"&C10 -> Горнодобывающий комплекс|Горный мастер | B10: Горнодобывающий комплекс | C10: Горный мастер | D10: Деятельность в сфере электроэнергетики, связанная с организацией и осуществлением монтажа, наладки, технического обслуживания, ремонта, управления режимом работы электроустановок (п.11 Приложения №2 к приказу 342н от 20.05.2022г.) Деятельность, связанная в сфере электроэнергетики, связанная с техническим обслуживанием, управлением режимом работы электроустановок (п.11 Приложения №2 к приказу 342н от 20.05.2022г.)
A11: =B11&"|"&C11 -> Горнодобывающий комплекс|Инженер | B11: Горнодобывающий комплекс | C11: Инженер | D11: Психиатрическое освидетельствование не требуется
A12: =B12&"|"&C12 -> Служба обслуживания и ремонта оборудования|Слесарь-ремонтник | B12: Служба обслуживания и ремонта оборудования | C12: Слесарь-ремонтник | D12: Деятельность, связанная в сфере электроэнергетики, связанная с техническим обслуживанием, управлением режимом работы электроустановок (п.11 Приложения №2 к приказу 342н от 20.05.2022г.)
A13: =B13&"|"&C13 -> Служба обслуживания и ремонта оборудования|Электромонтёр | B13: Служба обслуживания и ремонта оборудования | C13: Электромонтёр | D13: Психиатрическое освидетельствование не требуется
A14: =B14&"|"&C14 -> Служба обслуживания и ремонта оборудования|Механик | B14: Служба обслуживания и ремонта оборудования | C14: Механик | D14: Деятельность в сфере теплоснабжения, связанная с организацией и осуществлением монтажа, наладки, технического обслуживания, ремонта, управления режимом работы объектов теплоснабжения (п.12 Приложения №2 к приказу 342н от 20.05.2022г.) Деятельность по непосредственному забору, очистке и распределению воды питьевых нужд систем централизованного водоснабжения (п.7 Приложения №2 к приказу 342н от 20.05.2022г.)
A15: =B15&"|"&C15 -> Служба обслуживания и ремонта оборудования|Мастер по ремонту оборудования | B15: Служба обслуживания и ремонта оборудования | C15: Мастер по ремонту оборудования | D15: Психиатрическое освидетельствование не требуется
... A23: =B23&"|"&C23 -> Служба по работе с персоналом|Руководитель службы | B23: Служба по работе с персоналом | C23: Руководитель службы | D23: Психиатрическое освидетельствование не требуется
